---
title: Promise 链式调用
date: 2021-08-22 11:32:37
categories:
- ES6
comments: true
---

**resolve---->then**

- then 中是一个正常return ，得到resolve ，可以继续执行 .then里面的内容

- then 中是一个throw error，得到reject，不能执行后面的 .then

**rejected---->catch**

- catch 中是一个正常return ，得到resolve可以继续执行 .then里面的内容

- catch 中是一个error，得到reject ，不能执行后面的 .then，可以执行catch

<!-- more -->

## 例子1

```js
Promise.resolve().then(()=>{
  console.log(1);
}).catch(()=>{
  console.log(2);
}).then(()=>{
  console.log(3);
})
```

结果 1 3
第一个then中成功了，就相当于得到了一个resolve，resolve执行then，不执行catch，2不执行，3执行



## 例子2

```js
Promise.resolve().then(()=>{
  console.log(1);
  throw new Error("err")
}).catch(()=>{
  console.log(2);
}).then(()=>{
  console.log(3);
})
```

结果 1 2 3

第一个then中有throw err 出错了，相当于reject，reject执行catch，所以catch里面的内容正常执行，catch正常执行了，相当于resolve，resolve会执行then



## 例子3

```js
Promise.resolve().then(()=>{
  console.log(1);
  throw new Error("err")
}).catch(()=>{
  console.log(2);
}).catch(()=>{
  console.log(3);
})
```

结果 1 2
第一个then执行，里面有err ,相当于reject，执行catch，catch成功执行了，相当于resolved，执行then，不执行catch，所以2执行，3不执行



## 面试题1

```js
new Promise(() => {
  throw new Error()
}).then(() => {
  console.log(1)
}, () => {
  console.log(2)
}).catch(() => {
  console.log(3)
}).then(() => {
  console.log(4)
})
// 2 4
```

